<?xml version="1.0" encoding="UTF-8"?>
<testng-results ignored="1" total="3" passed="1" failed="1" skipped="0">
  <reporter-output>
  </reporter-output>
  <suite started-at="2018-04-01T11:50:15Z" name="Suite1" finished-at="2018-04-01T11:50:15Z" duration-ms="267">
    <groups>
      <group name="unit">
        <method signature="SampleTest.first()[pri:0, instance:samples.SampleTest@1ddf84b8]" name="first" class="samples.SampleTest"/>
      </group> <!-- unit -->
      <group name="web">
        <method signature="SampleTest.second()[pri:0, instance:samples.SampleTest@1ddf84b8]" name="second" class="samples.SampleTest"/>
      </group> <!-- web -->
    </groups>
    <test started-at="2018-04-01T11:50:15Z" name="test1" finished-at="2018-04-01T11:50:15Z" duration-ms="111">
      <class name="samples.SampleTest">
        <test-method signature="first()[pri:0, instance:samples.SampleTest@1ddf84b8]" started-at="2018-04-01T11:50:15Z" name="first" finished-at="2018-04-01T11:50:15Z" duration-ms="8" status="PASS">
          <reporter-output>
          </reporter-output>
        </test-method> <!-- first -->
        <test-method signature="second()[pri:0, instance:samples.SampleTest@1ddf84b8]" started-at="2018-04-01T11:50:15Z" name="second" finished-at="2018-04-01T11:50:15Z" duration-ms="3" status="FAIL">
          <exception class="java.lang.AssertionError">
            <message>
              <![CDATA[expected [1] but found [2]]]>
            </message>
            <full-stacktrace>
              <![CDATA[java.lang.AssertionError: expected [1] but found [2]
at org.testng.Assert.fail(Assert.java:96)
at org.testng.Assert.failNotEquals(Assert.java:776)
at org.testng.Assert.assertEqualsImpl(Assert.java:137)
at org.testng.Assert.assertEquals(Assert.java:118)
at org.testng.Assert.assertEquals(Assert.java:453)
at org.testng.Assert.assertEquals(Assert.java:463)
at samples.SampleTest.second(SampleTest.java:15)
at java.base/jdk.internal.reflect.NativeMethodAccessorImpl.invoke0(Native Method)
at java.base/jdk.internal.reflect.NativeMethodAccessorImpl.invoke(NativeMethodAccessorImpl.java:62)
at java.base/jdk.internal.reflect.DelegatingMethodAccessorImpl.invoke(DelegatingMethodAccessorImpl.java:43)
at java.base/java.lang.reflect.Method.invoke(Method.java:564)
at org.testng.internal.MethodInvocationHelper.invokeMethod(MethodInvocationHelper.java:124)
at org.testng.internal.Invoker.invokeMethod(Invoker.java:580)
at org.testng.internal.Invoker.invokeTestMethod(Invoker.java:716)
at org.testng.internal.Invoker.invokeTestMethods(Invoker.java:988)
at org.testng.internal.TestMethodWorker.invokeTestMethods(TestMethodWorker.java:125)
at org.testng.internal.TestMethodWorker.run(TestMethodWorker.java:109)
at org.testng.TestRunner.privateRun(TestRunner.java:648)
at org.testng.TestRunner.run(TestRunner.java:505)
at org.testng.SuiteRunner.runTest(SuiteRunner.java:455)
at org.testng.SuiteRunner.runSequentially(SuiteRunner.java:450)
at org.testng.SuiteRunner.privateRun(SuiteRunner.java:415)
at org.testng.SuiteRunner.run(SuiteRunner.java:364)
at org.testng.SuiteRunnerWorker.runSuite(SuiteRunnerWorker.java:52)
at org.testng.SuiteRunnerWorker.run(SuiteRunnerWorker.java:84)
at org.testng.TestNG.runSuitesSequentially(TestNG.java:1208)
at org.testng.TestNG.runSuitesLocally(TestNG.java:1137)
at org.testng.TestNG.runSuites(TestNG.java:1049)
at org.testng.TestNG.run(TestNG.java:1017)
at org.testng.IDEARemoteTestNG.run(IDEARemoteTestNG.java:72)
at org.testng.RemoteTestNGStarter.main(RemoteTestNGStarter.java:123)
]]>
            </full-stacktrace>
          </exception> <!-- java.lang.AssertionError -->
          <reporter-output>
          </reporter-output>
        </test-method> <!-- second -->
      </class> <!-- samples.SampleTest -->
    </test> <!-- test1 -->
    <test started-at="2018-04-01T11:50:15Z" name="test2" finished-at="2018-04-01T11:50:15Z" duration-ms="0">
    </test> <!-- test2 -->
  </suite> <!-- Suite1 -->
</testng-results>
