<?xml version="1.0" encoding="UTF-8"?>
<testng-results ignored="1" total="3" passed="1" failed="1" skipped="0">
  <reporter-output>
  </reporter-output>
  <suite started-at="2018-04-01T12:59:28Z" name="Suite1" finished-at="2018-04-01T12:59:28Z" duration-ms="79">
    <groups>
      <group name="unit">
        <method signature="SampleTest.first()[pri:0, instance:samples.SampleTest@5e82df6a]" name="first" class="samples.SampleTest"/>
      </group> <!-- unit -->
      <group name="web">
        <method signature="SampleTest.second()[pri:0, instance:samples.SampleTest@5e82df6a]" name="second" class="samples.SampleTest"/>
      </group> <!-- web -->
    </groups>
    <test started-at="2018-04-01T12:59:28Z" name="test2" finished-at="2018-04-01T12:59:28Z" duration-ms="8">
    </test> <!-- test2 -->
    <test started-at="2018-04-01T12:59:28Z" name="test1" finished-at="2018-04-01T12:59:28Z" duration-ms="79">
      <class name="samples.SampleTest">
        <test-method signature="first()[pri:0, instance:samples.SampleTest@5e82df6a]" started-at="2018-04-01T12:59:28Z" name="first" finished-at="2018-04-01T12:59:28Z" duration-ms="18" status="PASS">
          <reporter-output>
          </reporter-output>
        </test-method> <!-- first -->
        <test-method signature="second()[pri:0, instance:samples.SampleTest@5e82df6a]" started-at="2018-04-01T12:59:28Z" name="second" finished-at="2018-04-01T12:59:28Z" duration-ms="5" status="FAIL">
          <exception class="java.lang.AssertionError">
            <message>
              <![CDATA[expected [1] but found [2]]]>
            </message>
            <full-stacktrace>
              <![CDATA[java.lang.AssertionError: expected [1] but found [2]
at org.testng.Assert.fail(Assert.java:96)
at org.testng.Assert.failNotEquals(Assert.java:776)
at org.testng.Assert.assertEqualsImpl(Assert.java:137)
at org.testng.Assert.assertEquals(Assert.java:118)
at org.testng.Assert.assertEquals(Assert.java:453)
at org.testng.Assert.assertEquals(Assert.java:463)
at samples.SampleTest.second(SampleTest.java:15)
at java.base/jdk.internal.reflect.NativeMethodAccessorImpl.invoke0(Native Method)
at java.base/jdk.internal.reflect.NativeMethodAccessorImpl.invoke(NativeMethodAccessorImpl.java:62)
at java.base/jdk.internal.reflect.DelegatingMethodAccessorImpl.invoke(DelegatingMethodAccessorImpl.java:43)
at java.base/java.lang.reflect.Method.invoke(Method.java:564)
at org.testng.internal.MethodInvocationHelper.invokeMethod(MethodInvocationHelper.java:124)
at org.testng.internal.Invoker.invokeMethod(Invoker.java:580)
at org.testng.internal.Invoker.invokeTestMethod(Invoker.java:716)
at org.testng.internal.Invoker.invokeTestMethods(Invoker.java:988)
at org.testng.internal.TestMethodWorker.invokeTestMethods(TestMethodWorker.java:125)
at org.testng.internal.TestMethodWorker.run(TestMethodWorker.java:109)
at org.testng.TestRunner.privateRun(TestRunner.java:648)
at org.testng.TestRunner.run(TestRunner.java:505)
at org.testng.SuiteRunner.runTest(SuiteRunner.java:455)
at org.testng.SuiteRunner.access$000(SuiteRunner.java:40)
at org.testng.SuiteRunner$SuiteWorker.run(SuiteRunner.java:489)
at org.testng.internal.thread.ThreadUtil$1.call(ThreadUtil.java:52)
at java.base/java.util.concurrent.FutureTask.run(FutureTask.java:264)
at java.base/java.util.concurrent.ThreadPoolExecutor.runWorker(ThreadPoolExecutor.java:1135)
at java.base/java.util.concurrent.ThreadPoolExecutor$Worker.run(ThreadPoolExecutor.java:635)
at java.base/java.lang.Thread.run(Thread.java:844)
]]>
            </full-stacktrace>
          </exception> <!-- java.lang.AssertionError -->
          <reporter-output>
          </reporter-output>
        </test-method> <!-- second -->
      </class> <!-- samples.SampleTest -->
    </test> <!-- test1 -->
  </suite> <!-- Suite1 -->
</testng-results>
